2021-03-12 09:43:01,827 - django.security.csrf - WARNING - Forbidden (CSRF token missing or incorrect.): /api/upload/
2021-03-12 09:43:43,036 - django.utils.autoreload - INFO - /home/helloworld/Develops/Web_apps/pythonProject/diabetes/diabetes/settings.py changed, reloading.
2021-03-12 09:43:48,865 - django.request - ERROR - Internal Server Error: /api/upload/
Traceback (most recent call last):
  File "/home/helloworld/Develops/Web_apps/pythonProject/venv/lib/python3.8/site-packages/django/core/handlers/exception.py", line 47, in inner
    response = get_response(request)
  File "/home/helloworld/Develops/Web_apps/pythonProject/venv/lib/python3.8/site-packages/django/core/handlers/base.py", line 181, in _get_response
    response = wrapped_callback(request, *callback_args, **callback_kwargs)
TypeError: upload() missing 1 required positional argument: 'app_oath'
2021-03-12 09:43:59,904 - django.utils.autoreload - INFO - /home/helloworld/Develops/Web_apps/pythonProject/diabetes/api/upload.py changed, reloading.
2021-03-12 09:44:05,291 - django.request - ERROR - Internal Server Error: /api/upload/
Traceback (most recent call last):
  File "/home/helloworld/Develops/Web_apps/pythonProject/venv/lib/python3.8/site-packages/django/core/handlers/exception.py", line 47, in inner
    response = get_response(request)
  File "/home/helloworld/Develops/Web_apps/pythonProject/venv/lib/python3.8/site-packages/django/core/handlers/base.py", line 181, in _get_response
    response = wrapped_callback(request, *callback_args, **callback_kwargs)
  File "/home/helloworld/Develops/Web_apps/pythonProject/diabetes/api/upload.py", line 25, in upload
    res = upload_to_table()
  File "/home/helloworld/Develops/Web_apps/pythonProject/diabetes/api/upload.py", line 31, in upload_to_table
    data = pd.read_csv(url)
  File "/home/helloworld/Develops/Web_apps/pythonProject/venv/lib/python3.8/site-packages/pandas/io/parsers.py", line 610, in read_csv
    return _read(filepath_or_buffer, kwds)
  File "/home/helloworld/Develops/Web_apps/pythonProject/venv/lib/python3.8/site-packages/pandas/io/parsers.py", line 462, in _read
    parser = TextFileReader(filepath_or_buffer, **kwds)
  File "/home/helloworld/Develops/Web_apps/pythonProject/venv/lib/python3.8/site-packages/pandas/io/parsers.py", line 819, in __init__
    self._engine = self._make_engine(self.engine)
  File "/home/helloworld/Develops/Web_apps/pythonProject/venv/lib/python3.8/site-packages/pandas/io/parsers.py", line 1050, in _make_engine
    return mapping[engine](self.f, **self.options)  # type: ignore[call-arg]
  File "/home/helloworld/Develops/Web_apps/pythonProject/venv/lib/python3.8/site-packages/pandas/io/parsers.py", line 1867, in __init__
    self._open_handles(src, kwds)
  File "/home/helloworld/Develops/Web_apps/pythonProject/venv/lib/python3.8/site-packages/pandas/io/parsers.py", line 1362, in _open_handles
    self.handles = get_handle(
  File "/home/helloworld/Develops/Web_apps/pythonProject/venv/lib/python3.8/site-packages/pandas/io/common.py", line 642, in get_handle
    handle = open(
FileNotFoundError: [Errno 2] No such file or directory: 'frontend/src/assets/uploaded/dataset.csv'
2021-03-12 09:44:53,370 - django.utils.autoreload - INFO - /home/helloworld/Develops/Web_apps/pythonProject/diabetes/api/upload.py changed, reloading.
2021-03-12 09:45:33,318 - django.request - ERROR - Internal Server Error: /api/upload/
Traceback (most recent call last):
  File "/home/helloworld/Develops/Web_apps/pythonProject/venv/lib/python3.8/site-packages/django/core/handlers/exception.py", line 47, in inner
    response = get_response(request)
  File "/home/helloworld/Develops/Web_apps/pythonProject/venv/lib/python3.8/site-packages/django/core/handlers/base.py", line 181, in _get_response
    response = wrapped_callback(request, *callback_args, **callback_kwargs)
  File "/home/helloworld/Develops/Web_apps/pythonProject/diabetes/api/upload.py", line 25, in upload
    res = upload_to_table()
  File "/home/helloworld/Develops/Web_apps/pythonProject/diabetes/api/upload.py", line 36, in upload_to_table
    save_record.patient = f.userid
AttributeError: 'Pandas' object has no attribute 'userid'
2021-03-12 09:46:48,131 - django.utils.autoreload - INFO - /home/helloworld/Develops/Web_apps/pythonProject/diabetes/api/upload.py changed, reloading.
2021-03-12 09:47:08,810 - django.request - ERROR - Internal Server Error: /api/upload/
Traceback (most recent call last):
  File "/home/helloworld/Develops/Web_apps/pythonProject/venv/lib/python3.8/site-packages/django/core/handlers/exception.py", line 47, in inner
    response = get_response(request)
  File "/home/helloworld/Develops/Web_apps/pythonProject/venv/lib/python3.8/site-packages/django/core/handlers/base.py", line 181, in _get_response
    response = wrapped_callback(request, *callback_args, **callback_kwargs)
  File "/home/helloworld/Develops/Web_apps/pythonProject/diabetes/api/upload.py", line 25, in upload
    res = upload_to_table()
  File "/home/helloworld/Develops/Web_apps/pythonProject/diabetes/api/upload.py", line 36, in upload_to_table
    save_record.patient = f.patient
AttributeError: 'Pandas' object has no attribute 'patient'
2021-03-12 09:49:36,904 - django.utils.autoreload - INFO - /home/helloworld/Develops/Web_apps/pythonProject/diabetes/api/upload.py changed, reloading.
2021-03-12 09:50:14,424 - django.utils.autoreload - INFO - /home/helloworld/Develops/Web_apps/pythonProject/diabetes/api/upload.py changed, reloading.
2021-03-12 10:17:34,623 - django.utils.autoreload - INFO - /home/helloworld/Develops/Web_apps/pythonProject/diabetes/api/urls.py changed, reloading.
2021-03-12 10:18:24,809 - django.utils.autoreload - INFO - /home/helloworld/Develops/Web_apps/pythonProject/diabetes/api/urls.py changed, reloading.
2021-03-12 10:18:36,278 - django.utils.autoreload - INFO - /home/helloworld/Develops/Web_apps/pythonProject/diabetes/api/gets.py changed, reloading.
2021-03-12 10:19:00,397 - django.utils.autoreload - INFO - /home/helloworld/Develops/Web_apps/pythonProject/diabetes/api/gets.py changed, reloading.
2021-03-12 10:19:16,441 - django.utils.autoreload - INFO - /home/helloworld/Develops/Web_apps/pythonProject/diabetes/api/gets.py changed, reloading.
2021-03-12 10:19:26,467 - django.utils.autoreload - INFO - /home/helloworld/Develops/Web_apps/pythonProject/diabetes/api/upload.py changed, reloading.
2021-03-12 10:19:37,419 - django.utils.autoreload - INFO - /home/helloworld/Develops/Web_apps/pythonProject/diabetes/api/models.py changed, reloading.
2021-03-12 10:22:44,334 - django.utils.autoreload - INFO - /home/helloworld/Develops/Web_apps/pythonProject/diabetes/api/gets.py changed, reloading.
2021-03-12 10:29:21,907 - django.request - ERROR - Internal Server Error: /api/list_dataset/
Traceback (most recent call last):
  File "/home/helloworld/Develops/Web_apps/pythonProject/venv/lib/python3.8/site-packages/django/core/handlers/exception.py", line 47, in inner
    response = get_response(request)
  File "/home/helloworld/Develops/Web_apps/pythonProject/venv/lib/python3.8/site-packages/django/core/handlers/base.py", line 181, in _get_response
    response = wrapped_callback(request, *callback_args, **callback_kwargs)
  File "/home/helloworld/Develops/Web_apps/pythonProject/diabetes/api/gets.py", line 34, in get_dataset
    return JsonResponse(feedback, safe=False)
NameError: name 'JsonResponse' is not defined
2021-03-12 10:29:53,359 - django.utils.autoreload - INFO - /home/helloworld/Develops/Web_apps/pythonProject/diabetes/api/gets.py changed, reloading.
2021-03-12 12:17:46,908 - django.utils.autoreload - INFO - /home/helloworld/Develops/Web_apps/pythonProject/diabetes/api/gets.py changed, reloading.
2021-03-12 12:51:43,363 - django.utils.autoreload - INFO - /home/helloworld/Develops/Web_apps/pythonProject/diabetes/api/gets.py changed, reloading.
2021-03-12 13:47:27,224 - django.utils.autoreload - INFO - /home/helloworld/Develops/Web_apps/pythonProject/diabetes/api/testfile.py changed, reloading.
